2020-04-08 16:08:55,640 INFO: Microblog startup [in /home/centvr/Documents/pyscript/microblog/app/__init__.py: 70]
2020-04-08 16:22:17,893 INFO: Microblog startup [in /home/centvr/Documents/pyscript/microblog/app/__init__.py: 70]
2020-04-09 09:27:42,275 INFO: Microblog startup [in /home/centvr/Documents/pyscript/microblog/app/__init__.py: 70]
2020-04-09 09:29:27,244 ERROR: Exception on /main/user/milo [GET] [in /home/centvr/Documents/pyscript/microblog/venv/lib64/python3.6/site-packages/flask/app.py: 1891]
Traceback (most recent call last):
  File "/home/centvr/Documents/pyscript/microblog/venv/lib64/python3.6/site-packages/flask/app.py", line 2446, in wsgi_app
    response = self.full_dispatch_request()
  File "/home/centvr/Documents/pyscript/microblog/venv/lib64/python3.6/site-packages/flask/app.py", line 1951, in full_dispatch_request
    rv = self.handle_user_exception(e)
  File "/home/centvr/Documents/pyscript/microblog/venv/lib64/python3.6/site-packages/flask/app.py", line 1820, in handle_user_exception
    reraise(exc_type, exc_value, tb)
  File "/home/centvr/Documents/pyscript/microblog/venv/lib64/python3.6/site-packages/flask/_compat.py", line 39, in reraise
    raise value
  File "/home/centvr/Documents/pyscript/microblog/venv/lib64/python3.6/site-packages/flask/app.py", line 1949, in full_dispatch_request
    rv = self.dispatch_request()
  File "/home/centvr/Documents/pyscript/microblog/venv/lib64/python3.6/site-packages/flask/app.py", line 1935, in dispatch_request
    return self.view_functions[rule.endpoint](**req.view_args)
  File "/home/centvr/Documents/pyscript/microblog/venv/lib64/python3.6/site-packages/flask_login/utils.py", line 272, in decorated_view
    return func(*args, **kwargs)
  File "/home/centvr/Documents/pyscript/microblog/app/main/routes.py", line 50, in user
    next_url=next_url,prev_url=prev_url)
  File "/home/centvr/Documents/pyscript/microblog/venv/lib64/python3.6/site-packages/flask/templating.py", line 138, in render_template
    ctx.app.jinja_env.get_or_select_template(template_name_or_list),
  File "/home/centvr/Documents/pyscript/microblog/venv/lib64/python3.6/site-packages/jinja2/environment.py", line 930, in get_or_select_template
    return self.get_template(template_name_or_list, parent, globals)
  File "/home/centvr/Documents/pyscript/microblog/venv/lib64/python3.6/site-packages/jinja2/environment.py", line 883, in get_template
    return self._load_template(name, self.make_globals(globals))
  File "/home/centvr/Documents/pyscript/microblog/venv/lib64/python3.6/site-packages/jinja2/environment.py", line 857, in _load_template
    template = self.loader.load(self, name, globals)
  File "/home/centvr/Documents/pyscript/microblog/venv/lib64/python3.6/site-packages/jinja2/loaders.py", line 129, in load
    code = environment.compile(source, name, filename)
  File "/home/centvr/Documents/pyscript/microblog/venv/lib64/python3.6/site-packages/jinja2/environment.py", line 638, in compile
    self.handle_exception(source=source_hint)
  File "/home/centvr/Documents/pyscript/microblog/venv/lib64/python3.6/site-packages/jinja2/environment.py", line 832, in handle_exception
    reraise(*rewrite_traceback_stack(source=source))
  File "/home/centvr/Documents/pyscript/microblog/venv/lib64/python3.6/site-packages/jinja2/_compat.py", line 28, in reraise
    raise value.with_traceback(tb)
  File "/home/centvr/Documents/pyscript/microblog/app/templates/user.html", line 87, in template
    {% endblock %}
jinja2.exceptions.TemplateSyntaxError: Encountered unknown tag 'endblock'. You probably made a nesting mistake. Jinja is expecting this tag, but currently looking for 'elif' or 'else' or 'endif'. The innermost block that needs to be closed is 'if'.
2020-04-09 09:31:07,827 INFO: Microblog startup [in /home/centvr/Documents/pyscript/microblog/app/__init__.py: 70]
2020-04-09 09:32:18,828 INFO: Microblog startup [in /home/centvr/Documents/pyscript/microblog/app/__init__.py: 70]
2020-04-09 10:33:08,997 INFO: Microblog startup [in /home/centvr/Documents/pyscript/microblog/app/__init__.py: 72]
2020-04-09 10:33:32,614 ERROR: Exception on /main/export_posts [GET] [in /home/centvr/Documents/pyscript/microblog/venv/lib64/python3.6/site-packages/flask/app.py: 1891]
Traceback (most recent call last):
  File "/home/centvr/Documents/pyscript/microblog/venv/lib64/python3.6/site-packages/flask/app.py", line 2446, in wsgi_app
    response = self.full_dispatch_request()
  File "/home/centvr/Documents/pyscript/microblog/venv/lib64/python3.6/site-packages/flask/app.py", line 1951, in full_dispatch_request
    rv = self.handle_user_exception(e)
  File "/home/centvr/Documents/pyscript/microblog/venv/lib64/python3.6/site-packages/flask/app.py", line 1820, in handle_user_exception
    reraise(exc_type, exc_value, tb)
  File "/home/centvr/Documents/pyscript/microblog/venv/lib64/python3.6/site-packages/flask/_compat.py", line 39, in reraise
    raise value
  File "/home/centvr/Documents/pyscript/microblog/venv/lib64/python3.6/site-packages/flask/app.py", line 1949, in full_dispatch_request
    rv = self.dispatch_request()
  File "/home/centvr/Documents/pyscript/microblog/venv/lib64/python3.6/site-packages/flask/app.py", line 1935, in dispatch_request
    return self.view_functions[rule.endpoint](**req.view_args)
  File "/home/centvr/Documents/pyscript/microblog/venv/lib64/python3.6/site-packages/flask_login/utils.py", line 272, in decorated_view
    return func(*args, **kwargs)
  File "/home/centvr/Documents/pyscript/microblog/app/main/routes.py", line 185, in export_posts
    current_user.launch_task('export_posts',_('Exporting posts...'))
  File "/home/centvr/Documents/pyscript/microblog/app/models.py", line 127, in launch_task
    task = Task(id=rq_job.get_id(),name=name,description=decription,user=self)
NameError: name 'decription' is not defined
2020-04-09 10:35:37,974 INFO: Microblog startup [in /home/centvr/Documents/pyscript/microblog/app/__init__.py: 72]
2020-04-09 10:36:08,932 ERROR: Exception on /main/user/milo [GET] [in /home/centvr/Documents/pyscript/microblog/venv/lib64/python3.6/site-packages/flask/app.py: 1891]
Traceback (most recent call last):
  File "/home/centvr/Documents/pyscript/microblog/app/models.py", line 184, in get_rq_job
    rq_job = rq.job.Job.fetch(self.id,connection=currernt_app.redis)
NameError: name 'currernt_app' is not defined

During handling of the above exception, another exception occurred:

Traceback (most recent call last):
  File "/home/centvr/Documents/pyscript/microblog/venv/lib64/python3.6/site-packages/flask/app.py", line 2446, in wsgi_app
    response = self.full_dispatch_request()
  File "/home/centvr/Documents/pyscript/microblog/venv/lib64/python3.6/site-packages/flask/app.py", line 1951, in full_dispatch_request
    rv = self.handle_user_exception(e)
  File "/home/centvr/Documents/pyscript/microblog/venv/lib64/python3.6/site-packages/flask/app.py", line 1820, in handle_user_exception
    reraise(exc_type, exc_value, tb)
  File "/home/centvr/Documents/pyscript/microblog/venv/lib64/python3.6/site-packages/flask/_compat.py", line 39, in reraise
    raise value
  File "/home/centvr/Documents/pyscript/microblog/venv/lib64/python3.6/site-packages/flask/app.py", line 1949, in full_dispatch_request
    rv = self.dispatch_request()
  File "/home/centvr/Documents/pyscript/microblog/venv/lib64/python3.6/site-packages/flask/app.py", line 1935, in dispatch_request
    return self.view_functions[rule.endpoint](**req.view_args)
  File "/home/centvr/Documents/pyscript/microblog/venv/lib64/python3.6/site-packages/flask_login/utils.py", line 272, in decorated_view
    return func(*args, **kwargs)
  File "/home/centvr/Documents/pyscript/microblog/app/main/routes.py", line 50, in user
    next_url=next_url,prev_url=prev_url)
  File "/home/centvr/Documents/pyscript/microblog/venv/lib64/python3.6/site-packages/flask/templating.py", line 140, in render_template
    ctx.app,
  File "/home/centvr/Documents/pyscript/microblog/venv/lib64/python3.6/site-packages/flask/templating.py", line 120, in _render
    rv = template.render(context)
  File "/home/centvr/Documents/pyscript/microblog/venv/lib64/python3.6/site-packages/jinja2/environment.py", line 1090, in render
    self.environment.handle_exception()
  File "/home/centvr/Documents/pyscript/microblog/venv/lib64/python3.6/site-packages/jinja2/environment.py", line 832, in handle_exception
    reraise(*rewrite_traceback_stack(source=source))
  File "/home/centvr/Documents/pyscript/microblog/venv/lib64/python3.6/site-packages/jinja2/_compat.py", line 28, in reraise
    raise value.with_traceback(tb)
  File "/home/centvr/Documents/pyscript/microblog/app/templates/user.html", line 1, in top-level template code
    {% extends "base.html" %}
  File "/home/centvr/Documents/pyscript/microblog/app/templates/base.html", line 1, in top-level template code
    {% extends 'bootstrap/base.html' %}
  File "/home/centvr/Documents/pyscript/microblog/venv/lib64/python3.6/site-packages/flask_bootstrap/templates/bootstrap/base.html", line 1, in top-level template code
    {% block doc -%}
  File "/home/centvr/Documents/pyscript/microblog/venv/lib64/python3.6/site-packages/flask_bootstrap/templates/bootstrap/base.html", line 3, in block "doc"
    <html{% block html_attribs %}{% endblock html_attribs %}>
  File "/home/centvr/Documents/pyscript/microblog/venv/lib64/python3.6/site-packages/flask_bootstrap/templates/bootstrap/base.html", line 11, in block "html"
    {%- endblock metas %}
  File "/home/centvr/Documents/pyscript/microblog/venv/lib64/python3.6/site-packages/flask_bootstrap/templates/bootstrap/base.html", line 13, in block "body"
    {%- block styles %}
  File "/home/centvr/Documents/pyscript/microblog/app/templates/base.html", line 75, in block "content"
    <span id="{{ task.id }}-progress">{{ task.get_progress() }}</span>%
  File "/home/centvr/Documents/pyscript/microblog/app/models.py", line 190, in get_progress
    job = self.get_rq_job()
  File "/home/centvr/Documents/pyscript/microblog/app/models.py", line 185, in get_rq_job
    except (redis.exceptions.RedisError,rq.exceptions.NoSuchJobErroro):
AttributeError: module 'rq.exceptions' has no attribute 'NoSuchJobErroro'
